INFO:root:your text goes here
ERROR:fuse:Uncaught exception from FUSE operation destroy, returning errno.EINVAL.
Traceback (most recent call last):
  File "/home/veloso/.local/lib/python3.8/site-packages/fuse.py", line 734, in _wrapper
    return func(*args, **kwargs) or 0
  File "/home/veloso/.local/lib/python3.8/site-packages/fuse.py", line 992, in destroy
    return self.operations('destroy', '/')
  File "/home/veloso/.local/lib/python3.8/site-packages/fuse.py", line 1076, in __call__
    return getattr(self, op)(*args)
  File "myfuse.py", line 33, in destroy
    self.logs.close()
AttributeError: 'NoneType' object has no attribute 'close'
INFO:root:your text goes here
ERROR:root:your text goes here
ERROR:fuse:Uncaught exception from FUSE operation open, returning errno.EINVAL.
Traceback (most recent call last):
  File "/home/veloso/.local/lib/python3.8/site-packages/fuse.py", line 734, in _wrapper
    return func(*args, **kwargs) or 0
  File "/home/veloso/.local/lib/python3.8/site-packages/fuse.py", line 834, in open
    fi.fh = self.operations('open', path.decode(self.encoding),
  File "/home/veloso/.local/lib/python3.8/site-packages/fuse.py", line 1076, in __call__
    return getattr(self, op)(*args)
  File "myfuse.py", line 103, in open
    logging.log("asd")
TypeError: log() missing 1 required positional argument: 'msg'
INFO:root:your text goes here
ERROR:root:your text goes here
ERROR:fuse:Uncaught exception from FUSE operation open, returning errno.EINVAL.
Traceback (most recent call last):
  File "/home/veloso/.local/lib/python3.8/site-packages/fuse.py", line 734, in _wrapper
    return func(*args, **kwargs) or 0
  File "/home/veloso/.local/lib/python3.8/site-packages/fuse.py", line 834, in open
    fi.fh = self.operations('open', path.decode(self.encoding),
  File "/home/veloso/.local/lib/python3.8/site-packages/fuse.py", line 1076, in __call__
    return getattr(self, op)(*args)
  File "myfuse.py", line 103, in open
    logging.log("asd")
TypeError: log() missing 1 required positional argument: 'msg'
ERROR:fuse:Uncaught exception from FUSE operation destroy, returning errno.EINVAL.
Traceback (most recent call last):
  File "/home/veloso/.local/lib/python3.8/site-packages/fuse.py", line 734, in _wrapper
    return func(*args, **kwargs) or 0
  File "/home/veloso/.local/lib/python3.8/site-packages/fuse.py", line 992, in destroy
    return self.operations('destroy', '/')
  File "/home/veloso/.local/lib/python3.8/site-packages/fuse.py", line 1076, in __call__
    return getattr(self, op)(*args)
  File "myfuse.py", line 33, in destroy
    self.logs.close()
AttributeError: 'NoneType' object has no attribute 'close'
INFO:root:your text goes here
ERROR:root:your text goes here
ERROR:fuse:Uncaught exception from FUSE operation destroy, returning errno.EINVAL.
Traceback (most recent call last):
  File "/home/veloso/.local/lib/python3.8/site-packages/fuse.py", line 734, in _wrapper
    return func(*args, **kwargs) or 0
  File "/home/veloso/.local/lib/python3.8/site-packages/fuse.py", line 992, in destroy
    return self.operations('destroy', '/')
  File "/home/veloso/.local/lib/python3.8/site-packages/fuse.py", line 1076, in __call__
    return getattr(self, op)(*args)
  File "myfuse.py", line 33, in destroy
    self.logs.close()
AttributeError: 'NoneType' object has no attribute 'close'
